Workbook
Name adm0_list: _xlfn.ANCHORARRAY(_validation!$B$3)
Name boolean_flag: _validation!$G$3:$G$4
Name CountrySelected: '1. Describe Your Emergency'!$A$1
Name IndicatorsDefined: '2. Define Indicators'!$A$1
Name pillars_var: _validation!$D$4:$D$6
Name status_var: _validation!$I$4:$I$8
Name tbl_pill_weights: '4. Define Weights'!$B$8:$C$12
Name WeightsDefined: '4. Define Weights'!$A$1

Sheet Instructions
B2: Description:
B3: This workbook provides a quantitative framework for assessing public health risk related to extreme temperature conditions in acute emergency settings. It is designed to support operational preparedness and response planning across different climates and seasonal contexts, enabling analysts to examine how exposure, vulnerability, and coping capacity interact to shape subnational-level risk. The tool applies a composite indicator methodology, allowing users to replicate, adapt, and iterate the model for repeated assessments or for use in other settings. To inform preparedness and response decision-making, the model integrates multiple indicators drawn from environmental, demographic, socioeconomic, and health-related datasets. These indicators are organized under three analytical pillars: Exposure – e.g. climate and environmental factors Vulnerability – e.g. population characteristics and socioeconomic conditions Coping Capacity – e.g. access to services, institutional resilience, and infrastructure-related factors Each indicator contributes to an overall subnational-level score reflecting relative risk. By adjusting indicator selection and weighting, analysts can explore alternative risk configurations and assess the sensitivity of results under different assumptions.
B5: Details:
B6: The tool includes the following tabs: 1. Describe Your Acute Emergency – Define the emergency context, including location, time of assessment, and team. 2. Define Indicators – Select indicators for each pillar. Document your sources, assess data availability, and record decisions about what to include or exclude. 3. Enter Indicator Scores – Input normalized scores for each indicator at the sub-national level. 4. Define Weights – Assign relative weights to each indicator based on analytical priorities or expert judgment. 5. Weighted Indicator Scores – Review the calculated weighted scores for each indicator. 6. Composite Risk Scores – View the final subnational-level risk scores and explore results. Export result for mapping in R or GIS.
B7: Before getting started: - Modify only the designated input cells (highlighted in light grey). Do not rename or delete tabs, headers, or key column; inter-sheet formulas depend on these structures. - Verify that all weights sum to 1.00 (or 100%) before interpreting results. - Save a copy before making structural edits to protect dependencies.
B9: WHO/filepath
B10: © WHO 2026. Some rights reserved. This work is available under the CC BY-NC-SA 3.0 IGO licence.

Sheet 1. Describe Your Emergency
A1: =$D$6<>"" -> FALSE
B2: Step 1. Describe Your Acute Emergency
C3: What is the context of your acute emergency?
C4: Instuctions: For each question, input your answer to briefly address the question.
C5: 1. Acute Emergency Name
C6: 2. Host Country
C7: 3. WHO Region
C8: 4. Date of Risk Assessment
C9: 6. Description of Acute Emergency
C10: 5. Assessment Team Members and Role (i.e. leader etc.)
C16: WHO/filepath
C17: © WHO 2026. Some rights reserved. This work is available under the CC BY-NC-SA 3.0 IGO licence.

Sheet 2. Define Indicators
A1: =COUNTA('2. Define Indicators'!$E7:$E99)>0 -> FALSE
C2: Step 2. Define Indicators
C3: Which indicators are relevant, available, and appropriate to include?
C4: Instructions: For each indicator, document the following: - Data availability: Indicate whether data exists and is accessible. - Source details: Specify the origin of the data. - Analytical choices: Describe how the data will be processed, including normalization or transformation (e.g., scaling, binning). - Include column: Indicate whether the indicator should be incorporated into the model based on relevance, data quality, and uniqueness. Guidance for review and additions: - Ensure each indicator provides distinct, meaningful information; avoid duplication. - Engage experts on the ground or in the field to validate that each indicator matters and that no key indicators are missing. - To propose a new indicator, add a new row. - To rename an existing indicator, edit the label only. - Do not reuse an existing indicator row for a different concept.
B6: Indicator ID | C6: Indicator | D6: Subpillar | E6: Pillar | F6: Data Available | G6: Data Source | H6: Filename / URL | I6: Time Period | J6: Include | K6: Rationale | L6: Normalization Procedure | M6: Status | N6: Comments
B7: {="IND_" & _xlfn.SWITCH(E7, "Exposure","EXP", "Vulnerability","VUL", "Coping Capacity","COP", "UNK" ) & "_" & TEXT( COUNTIF($E$7:E7, E7), "00")} -> IND_UNK_00
B8: {="IND_" & _xlfn.SWITCH(E8, "Exposure","EXP", "Vulnerability","VUL", "Coping Capacity","COP", "UNK" ) & "_" & TEXT( COUNTIF($E$7:E8, E8), "00")} -> IND_UNK_00
B9: {="IND_" & _xlfn.SWITCH(E9, "Exposure","EXP", "Vulnerability","VUL", "Coping Capacity","COP", "UNK" ) & "_" & TEXT( COUNTIF($E$7:E9, E9), "00")} -> IND_UNK_00
B10: {="IND_" & _xlfn.SWITCH(E10, "Exposure","EXP", "Vulnerability","VUL", "Coping Capacity","COP", "UNK" ) & "_" & TEXT( COUNTIF($E$7:E10, E10), "00")} -> IND_UNK_00
B11: {="IND_" & _xlfn.SWITCH(E11, "Exposure","EXP", "Vulnerability","VUL", "Coping Capacity","COP", "UNK" ) & "_" & TEXT( COUNTIF($E$7:E11, E11), "00")} -> IND_UNK_00
B12: {="IND_" & _xlfn.SWITCH(E12, "Exposure","EXP", "Vulnerability","VUL", "Coping Capacity","COP", "UNK" ) & "_" & TEXT( COUNTIF($E$7:E12, E12), "00")} -> IND_UNK_00
B13: {="IND_" & _xlfn.SWITCH(E13, "Exposure","EXP", "Vulnerability","VUL", "Coping Capacity","COP", "UNK" ) & "_" & TEXT( COUNTIF($E$7:E13, E13), "00")} -> IND_UNK_00
B14: {="IND_" & _xlfn.SWITCH(E14, "Exposure","EXP", "Vulnerability","VUL", "Coping Capacity","COP", "UNK" ) & "_" & TEXT( COUNTIF($E$7:E14, E14), "00")} -> IND_UNK_00
B15: {="IND_" & _xlfn.SWITCH(E15, "Exposure","EXP", "Vulnerability","VUL", "Coping Capacity","COP", "UNK" ) & "_" & TEXT( COUNTIF($E$7:E15, E15), "00")} -> IND_UNK_00
B16: {="IND_" & _xlfn.SWITCH(E16, "Exposure","EXP", "Vulnerability","VUL", "Coping Capacity","COP", "UNK" ) & "_" & TEXT( COUNTIF($E$7:E16, E16), "00")} -> IND_UNK_00
B17: {="IND_" & _xlfn.SWITCH(E17, "Exposure","EXP", "Vulnerability","VUL", "Coping Capacity","COP", "UNK" ) & "_" & TEXT( COUNTIF($E$7:E17, E17), "00")} -> IND_UNK_00
B18: {="IND_" & _xlfn.SWITCH(E18, "Exposure","EXP", "Vulnerability","VUL", "Coping Capacity","COP", "UNK" ) & "_" & TEXT( COUNTIF($E$7:E18, E18), "00")} -> IND_UNK_00
... B24: {="IND_" & _xlfn.SWITCH(E24, "Exposure","EXP", "Vulnerability","VUL", "Coping Capacity","COP", "UNK" ) & "_" & TEXT( COUNTIF($E$7:E24, E24), "00")} -> IND_UNK_00
C28: WHO/filepath
C29: © WHO 2026. Some rights reserved. This work is available under the CC BY-NC-SA 3.0 IGO licence.

Sheet 3. Enter Indicator Scores
B2: Step 3. Enter Indicator Scores
B3: What are the indicator scores for each subnational area?
B4: Instructions: For each indicator selected (marked "Include" in Step 2), enter scores for every subnational unit. Guidance for filling the values: - Use normalized scores for comparability across indicators. - Ensure consistent directionality (e.g., higher scores should indicate higher risk). - Leave cells blank only if data is unavailable; document any gaps in Step 2.
B5: =IF(IndicatorsDefined,"","First define indicators in Step 2. Once at least one indicator is selected, a table will appear here where you can enter indicator scores for each subnational unit.") -> First define indicators in Step 2. Once at least one indicator is selected, a table will appear here where you can enter indicator scores for each subnational unit.
D7: =IF( D$9="", "", _xlfn.XLOOKUP( D$9, tbl_define_indicators[Indicator ID], tbl_define_indicators[Pillar] ) ) | E7: =IF( E$9="", "", _xlfn.XLOOKUP( E$9, tbl_define_indicators[Indicator ID], tbl_define_indicators[Pillar] ) ) | F7: =IF( F$9="", "", _xlfn.XLOOKUP( F$9, tbl_define_indicators[Indicator ID], tbl_define_indicators[Pillar] ) ) | G7: =IF( G$9="", "", _xlfn.XLOOKUP( G$9, tbl_define_indicators[Indicator ID], tbl_define_indicators[Pillar] ) ) | H7: =IF( H$9="", "", _xlfn.XLOOKUP( H$9, tbl_define_indicators[Indicator ID], tbl_define_indicators[Pillar] ) ) | I7: =IF( I$9="", "", _xlfn.XLOOKUP( I$9, tbl_define_indicators[Indicator ID], tbl_define_indicators[Pillar] ) ) | J7: =IF( J$9="", "", _xlfn.XLOOKUP( J$9, tbl_define_indicators[Indicator ID], tbl_define_indicators[Pillar] ) ) | K7: =IF( K$9="", "", _xlfn.XLOOKUP( K$9, tbl_define_indicators[Indicator ID], tbl_define_indicators[Pillar] ) ) | ... CZ7: =IF( CZ$9="", "", _xlfn.XLOOKUP( CZ$9, tbl_define_indicators[Indicator ID], tbl_define_indicators[Pillar] ) )
B8: Country / Territory | C8: Subnational Level | D8: =IF( D$9="", "", _xlfn.XLOOKUP( D$9, tbl_define_indicators[Indicator ID], tbl_define_indicators[Indicator] ) ) | E8: =IF( E$9="", "", _xlfn.XLOOKUP( E$9, tbl_define_indicators[Indicator ID], tbl_define_indicators[Indicator] ) ) | F8: =IF( F$9="", "", _xlfn.XLOOKUP( F$9, tbl_define_indicators[Indicator ID], tbl_define_indicators[Indicator] ) ) | G8: =IF( G$9="", "", _xlfn.XLOOKUP( G$9, tbl_define_indicators[Indicator ID], tbl_define_indicators[Indicator] ) ) | H8: =IF( H$9="", "", _xlfn.XLOOKUP( H$9, tbl_define_indicators[Indicator ID], tbl_define_indicators[Indicator] ) ) | I8: =IF( I$9="", "", _xlfn.XLOOKUP( I$9, tbl_define_indicators[Indicator ID], tbl_define_indicators[Indicator] ) ) | J8: =IF( J$9="", "", _xlfn.XLOOKUP( J$9, tbl_define_indicators[Indicator ID], tbl_define_indicators[Indicator] ) ) | K8: =IF( K$9="", "", _xlfn.XLOOKUP( K$9, tbl_define_indicators[Indicator ID], tbl_define_indicators[Indicator] ) ) | ... CZ8: =IF( CZ$9="", "", _xlfn.XLOOKUP( CZ$9, tbl_define_indicators[Indicator ID], tbl_define_indicators[Indicator] ) )
D9: {=IF( IndicatorsDefined, TRANSPOSE( _xlfn._xlws.FILTER( tbl_define_indicators[Indicator ID], tbl_define_indicators[Include]=TRUE ) ), "" )}
B10: {=IF( CountrySelected, _xlfn._xlws.FILTER( tbl_geo[Country / Territory], tbl_geo[Country / Territory]='1. Describe Your Emergency'!$D$6 ), "" )} | C10: {=IF( CountrySelected, _xlfn._xlws.FILTER( tbl_geo[Subnational Level], tbl_geo[Country / Territory]='1. Describe Your Emergency'!$D$6 ), "" )}

Sheet 4. Define Weights
A1: =AND( ABS(C12-1)<0.0001, ABS(L12-1)<0.0001 ) -> FALSE
B2: Step 4. Define Weights
B3: How should the relative importance of each Pillar and Indicator be weighted?
B4: Instructions: - Assign a weight to each pillar and to each indicator. - Pillar weights must sum to 1.00 overall. - Indicator weights must sum to 1.00 within each pillar. Guidance on weighting: - If no strong basis exists for differentiation, start with equal weights. - Adjust weights based on expert judgment, local knowledge, or sensitivity analysis. - Document your rationale for any weighting decisions in Step 2.
B5: =IF(IndicatorsDefined,"","First define indicators in Step 2. Once at least one indicator is selected, tables will appear here where you can enter pillar and indicator weights.") -> First define indicators in Step 2. Once at least one indicator is selected, tables will appear here where you can enter pillar and indicator weights.
B7: Step 4A. Define Pillar Weights (must sum to 100%) | F7: Step 4B. Define Indicator Weights | K7: Step 4C. Validate Indicator Weights (must sum to 100%)
B8: Pillar | C8: Pillar Weight | E8: Indicator ID | F8: Indicator | G8: Pillar | H8: Indicator Weight | I8: Overall Weight | K8: Pillar | L8: Sum
B9: Exposure | E9: {=_xlfn._xlws.FILTER( tbl_define_indicators[Indicator ID], tbl_define_indicators[Include]=TRUE )} -> #VALUE! | F9: {=IF( IndicatorsDefined, _xlfn._xlws.FILTER( CHOOSE({1,2}, tbl_define_indicators[Indicator], tbl_define_indicators[Pillar] ), tbl_define_indicators[Include]=TRUE ), "" )} | I9: =IF( OR($G9="",$H9=""), "", $H9*_xlfn.XLOOKUP($G9,'4. Define Weights'!$B$9:$B$12,'4. Define Weights'!$C$9:$C$12 ) ) | K9: Exposure | L9: =SUMIF($G$9:$G$100, K9,$H$9:$H$100 ) -> 0
B10: Vulnerability | I10: =IF( OR($G10="",$H10=""), "", $H10*_xlfn.XLOOKUP($G10,'4. Define Weights'!$B$9:$B$12,'4. Define Weights'!$C$9:$C$12 ) ) | K10: Vulnerability | L10: =SUMIF($G$9:$G$100, K10,$H$9:$H$100 ) -> 0
B11: Coping Capacity | I11: =IF( OR($G11="",$H11=""), "", $H11*_xlfn.XLOOKUP($G11,'4. Define Weights'!$B$9:$B$12,'4. Define Weights'!$C$9:$C$12 ) ) | K11: Coping Capacity | L11: =SUMIF($G$9:$G$100, K11,$H$9:$H$100 ) -> 0
B12: TOTAL | C12: =SUM($C$9:$C$11) -> 0 | I12: =IF( OR($G12="",$H12=""), "", $H12*_xlfn.XLOOKUP($G12,'4. Define Weights'!$B$9:$B$12,'4. Define Weights'!$C$9:$C$12 ) ) | K12: TOTAL | L12: =SUM(I9:I100) -> 0
I13: =IF( OR($G13="",$H13=""), "", $H13*_xlfn.XLOOKUP($G13,'4. Define Weights'!$B$9:$B$12,'4. Define Weights'!$C$9:$C$12 ) )
B14: =IF( COUNT($C$9:$C$11)=0, "Define pillar weights in the table above.", IF( ABS($C$12-1)<0.0001, "Pillar weights are valid. Total equals 100%.", "Pillar weights must sum to 100%. Please adjust." ) ) -> Define pillar weights in the table above. | I14: =IF( OR($G14="",$H14=""), "", $H14*_xlfn.XLOOKUP($G14,'4. Define Weights'!$B$9:$B$12,'4. Define Weights'!$C$9:$C$12 ) ) | K14: {=IF( SUM($L$9:$L$11)=0, "Define indicator weights in the table to the left.", IF( COUNTIF($L$9:$L$11,"<>1")=0, "Indicator weights are valid. Each pillar sums to 100%.", "Indicator weights are invalid for: " & _xlfn.TEXTJOIN( ", ", TRUE, _xlfn._xlws.FILTER($K$9:$K$11, ABS($L$9:$L$11-1)>0.0001) ) ) )} -> Define indicator weights in the table to the left.
I15: =IF( OR($G15="",$H15=""), "", $H15*_xlfn.XLOOKUP($G15,'4. Define Weights'!$B$9:$B$12,'4. Define Weights'!$C$9:$C$12 ) )
I16: =IF( OR($G16="",$H16=""), "", $H16*_xlfn.XLOOKUP($G16,'4. Define Weights'!$B$9:$B$12,'4. Define Weights'!$C$9:$C$12 ) )
I17: =IF( OR($G17="",$H17=""), "", $H17*_xlfn.XLOOKUP($G17,'4. Define Weights'!$B$9:$B$12,'4. Define Weights'!$C$9:$C$12 ) )
I18: =IF( OR($G18="",$H18=""), "", $H18*_xlfn.XLOOKUP($G18,'4. Define Weights'!$B$9:$B$12,'4. Define Weights'!$C$9:$C$12 ) )
I19: =IF( OR($G19="",$H19=""), "", $H19*_xlfn.XLOOKUP($G19,'4. Define Weights'!$B$9:$B$12,'4. Define Weights'!$C$9:$C$12 ) )
I20: =IF( OR($G20="",$H20=""), "", $H20*_xlfn.XLOOKUP($G20,'4. Define Weights'!$B$9:$B$12,'4. Define Weights'!$C$9:$C$12 ) )
I21: =IF( OR($G21="",$H21=""), "", $H21*_xlfn.XLOOKUP($G21,'4. Define Weights'!$B$9:$B$12,'4. Define Weights'!$C$9:$C$12 ) )
I22: =IF( OR($G22="",$H22=""), "", $H22*_xlfn.XLOOKUP($G22,'4. Define Weights'!$B$9:$B$12,'4. Define Weights'!$C$9:$C$12 ) )
I23: =IF( OR($G23="",$H23=""), "", $H23*_xlfn.XLOOKUP($G23,'4. Define Weights'!$B$9:$B$12,'4. Define Weights'!$C$9:$C$12 ) )
I24: =IF( OR($G24="",$H24=""), "", $H24*_xlfn.XLOOKUP($G24,'4. Define Weights'!$B$9:$B$12,'4. Define Weights'!$C$9:$C$12 ) )
I25: =IF( OR($G25="",$H25=""), "", $H25*_xlfn.XLOOKUP($G25,'4. Define Weights'!$B$9:$B$12,'4. Define Weights'!$C$9:$C$12 ) )
I26: =IF( OR($G26="",$H26=""), "", $H26*_xlfn.XLOOKUP($G26,'4. Define Weights'!$B$9:$B$12,'4. Define Weights'!$C$9:$C$12 ) )
... I100: =IF( OR($G100="",$H100=""), "", $H100*_xlfn.XLOOKUP($G100,'4. Define Weights'!$B$9:$B$12,'4. Define Weights'!$C$9:$C$12 ) )

Sheet 5. Weighted Indicator Scores
B2: Step 5. Review Weighted Indicator Scores
B3: How do weights affect each indicator's contribution to the risk level?
B4: Instuctions: - This tab calculates automatically based on your inputs in Steps 3 and 4. - Review the weighted scores to verify that indicator values and weights have been applied correctly. No manual input is required.
B5: =IF(IndicatorsDefined,"","First define pillar and indicator weights in Step 4. Once pillar and indicator weights sum to 1.0 or 100%, tables will appear here where you can review weighted scores.") -> First define pillar and indicator weights in Step 4. Once pillar and indicator weights sum to 1.0 or 100%, tables will appear here where you can review weighted scores.
D7: =IF( D$9="", "", _xlfn.XLOOKUP( D$9, tbl_define_indicators[Indicator ID], tbl_define_indicators[Pillar] ) ) | E7: =IF( E$9="", "", _xlfn.XLOOKUP( E$9, tbl_define_indicators[Indicator ID], tbl_define_indicators[Pillar] ) ) | F7: =IF( F$9="", "", _xlfn.XLOOKUP( F$9, tbl_define_indicators[Indicator ID], tbl_define_indicators[Pillar] ) ) | G7: =IF( G$9="", "", _xlfn.XLOOKUP( G$9, tbl_define_indicators[Indicator ID], tbl_define_indicators[Pillar] ) ) | H7: =IF( H$9="", "", _xlfn.XLOOKUP( H$9, tbl_define_indicators[Indicator ID], tbl_define_indicators[Pillar] ) ) | I7: =IF( I$9="", "", _xlfn.XLOOKUP( I$9, tbl_define_indicators[Indicator ID], tbl_define_indicators[Pillar] ) ) | J7: =IF( J$9="", "", _xlfn.XLOOKUP( J$9, tbl_define_indicators[Indicator ID], tbl_define_indicators[Pillar] ) ) | K7: =IF( K$9="", "", _xlfn.XLOOKUP( K$9, tbl_define_indicators[Indicator ID], tbl_define_indicators[Pillar] ) ) | ... CZ7: =IF( CZ$9="", "", _xlfn.XLOOKUP( CZ$9, tbl_define_indicators[Indicator ID], tbl_define_indicators[Pillar] ) )
D8: =IF( D$9="", "", _xlfn.XLOOKUP( D$9, tbl_define_indicators[Indicator ID], tbl_define_indicators[Indicator] ) ) | E8: =IF( E$9="", "", _xlfn.XLOOKUP( E$9, tbl_define_indicators[Indicator ID], tbl_define_indicators[Indicator] ) ) | F8: =IF( F$9="", "", _xlfn.XLOOKUP( F$9, tbl_define_indicators[Indicator ID], tbl_define_indicators[Indicator] ) ) | G8: =IF( G$9="", "", _xlfn.XLOOKUP( G$9, tbl_define_indicators[Indicator ID], tbl_define_indicators[Indicator] ) ) | H8: =IF( H$9="", "", _xlfn.XLOOKUP( H$9, tbl_define_indicators[Indicator ID], tbl_define_indicators[Indicator] ) ) | I8: =IF( I$9="", "", _xlfn.XLOOKUP( I$9, tbl_define_indicators[Indicator ID], tbl_define_indicators[Indicator] ) ) | J8: =IF( J$9="", "", _xlfn.XLOOKUP( J$9, tbl_define_indicators[Indicator ID], tbl_define_indicators[Indicator] ) ) | K8: =IF( K$9="", "", _xlfn.XLOOKUP( K$9, tbl_define_indicators[Indicator ID], tbl_define_indicators[Indicator] ) ) | ... CZ8: =IF( CZ$9="", "", _xlfn.XLOOKUP( CZ$9, tbl_define_indicators[Indicator ID], tbl_define_indicators[Indicator] ) )
D9: {=IF( AND(IndicatorsDefined, WeightsDefined), TRANSPOSE( _xlfn._xlws.FILTER( tbl_define_indicators[Indicator ID], tbl_define_indicators[Include]=TRUE ) ), "" )}
C11: Overall Weight: | D11: =IF(D$8="","",_xlfn.XLOOKUP(D$8,'4. Define Weights'!$F:$F,'4. Define Weights'!$I:$I,"")) | E11: =IF(E$8="","",_xlfn.XLOOKUP(E$8,'4. Define Weights'!$F:$F,'4. Define Weights'!$I:$I,"")) | F11: =IF(F$8="","",_xlfn.XLOOKUP(F$8,'4. Define Weights'!$F:$F,'4. Define Weights'!$I:$I,"")) | G11: =IF(G$8="","",_xlfn.XLOOKUP(G$8,'4. Define Weights'!$F:$F,'4. Define Weights'!$I:$I,"")) | H11: =IF(H$8="","",_xlfn.XLOOKUP(H$8,'4. Define Weights'!$F:$F,'4. Define Weights'!$I:$I,"")) | I11: =IF(I$8="","",_xlfn.XLOOKUP(I$8,'4. Define Weights'!$F:$F,'4. Define Weights'!$I:$I,"")) | J11: =IF(J$8="","",_xlfn.XLOOKUP(J$8,'4. Define Weights'!$F:$F,'4. Define Weights'!$I:$I,"")) | K11: =IF(K$8="","",_xlfn.XLOOKUP(K$8,'4. Define Weights'!$F:$F,'4. Define Weights'!$I:$I,"")) | ... CZ11: =IF(CZ$8="","",_xlfn.XLOOKUP(CZ$8,'4. Define Weights'!$F:$F,'4. Define Weights'!$I:$I,""))
B13: Country / Territory | C13: Subnational Level
B14: {=IF( CountrySelected, _xlfn._xlws.FILTER( tbl_geo[Country / Territory], tbl_geo[Country / Territory]='1. Describe Your Emergency'!$D$6 ), "" )} | C14: {=IF( CountrySelected, _xlfn._xlws.FILTER( tbl_geo[Subnational Level], tbl_geo[Country / Territory]='1. Describe Your Emergency'!$D$6 ), "" )} | D14: {=_xlfn.LET( _xlpm.w, D$11, _xlpm.r, MATCH(1,('3. Enter Indicator Scores'!$B$10:$B$161=$B14)*('3. Enter Indicator Scores'!$C$10:$C$161=$C14),0), _xlpm.c, MATCH(D$8,'3. Enter Indicator Scores'!$D$8:$CZ$8,0), _xlpm.v, IFERROR(INDEX('3. Enter Indicator Scores'!$D$10:$CZ$161,_xlpm.r,_xlpm.c),""), IF(OR(_xlpm.w="",_xlpm.v=""),"",_xlpm.v*_xlpm.w) )} | E14: {=_xlfn.LET( _xlpm.w, E$11, _xlpm.r, MATCH(1,('3. Enter Indicator Scores'!$B$10:$B$161=$B14)*('3. Enter Indicator Scores'!$C$10:$C$161=$C14),0), _xlpm.c, MATCH(E$8,'3. Enter Indicator Scores'!$D$8:$CZ$8,0), _xlpm.v, IFERROR(INDEX('3. Enter Indicator Scores'!$D$10:$CZ$161,_xlpm.r,_xlpm.c),""), IF(OR(_xlpm.w="",_xlpm.v=""),"",_xlpm.v*_xlpm.w) )} | F14: {=_xlfn.LET( _xlpm.w, F$11, _xlpm.r, MATCH(1,('3. Enter Indicator Scores'!$B$10:$B$161=$B14)*('3. Enter Indicator Scores'!$C$10:$C$161=$C14),0), _xlpm.c, MATCH(F$8,'3. Enter Indicator Scores'!$D$8:$CZ$8,0), _xlpm.v, IFERROR(INDEX('3. Enter Indicator Scores'!$D$10:$CZ$161,_xlpm.r,_xlpm.c),""), IF(OR(_xlpm.w="",_xlpm.v=""),"",_xlpm.v*_xlpm.w) )} | G14: {=_xlfn.LET( _xlpm.w, G$11, _xlpm.r, MATCH(1,('3. Enter Indicator Scores'!$B$10:$B$161=$B14)*('3. Enter Indicator Scores'!$C$10:$C$161=$C14),0), _xlpm.c, MATCH(G$8,'3. Enter Indicator Scores'!$D$8:$CZ$8,0), _xlpm.v, IFERROR(INDEX('3. Enter Indicator Scores'!$D$10:$CZ$161,_xlpm.r,_xlpm.c),""), IF(OR(_xlpm.w="",_xlpm.v=""),"",_xlpm.v*_xlpm.w) )} | H14: {=_xlfn.LET( _xlpm.w, H$11, _xlpm.r, MATCH(1,('3. Enter Indicator Scores'!$B$10:$B$161=$B14)*('3. Enter Indicator Scores'!$C$10:$C$161=$C14),0), _xlpm.c, MATCH(H$8,'3. Enter Indicator Scores'!$D$8:$CZ$8,0), _xlpm.v, IFERROR(INDEX('3. Enter Indicator Scores'!$D$10:$CZ$161,_xlpm.r,_xlpm.c),""), IF(OR(_xlpm.w="",_xlpm.v=""),"",_xlpm.v*_xlpm.w) )} | I14: {=_xlfn.LET( _xlpm.w, I$11, _xlpm.r, MATCH(1,('3. Enter Indicator Scores'!$B$10:$B$161=$B14)*('3. Enter Indicator Scores'!$C$10:$C$161=$C14),0), _xlpm.c, MATCH(I$8,'3. Enter Indicator Scores'!$D$8:$CZ$8,0), _xlpm.v, IFERROR(INDEX('3. Enter Indicator Scores'!$D$10:$CZ$161,_xlpm.r,_xlpm.c),""), IF(OR(_xlpm.w="",_xlpm.v=""),"",_xlpm.v*_xlpm.w) )} | J14: {=_xlfn.LET( _xlpm.w, J$11, _xlpm.r, MATCH(1,('3. Enter Indicator Scores'!$B$10:$B$161=$B14)*('3. Enter Indicator Scores'!$C$10:$C$161=$C14),0), _xlpm.c, MATCH(J$8,'3. Enter Indicator Scores'!$D$8:$CZ$8,0), _xlpm.v, IFERROR(INDEX('3. Enter Indicator Scores'!$D$10:$CZ$161,_xlpm.r,_xlpm.c),""), IF(OR(_xlpm.w="",_xlpm.v=""),"",_xlpm.v*_xlpm.w) )} | K14: {=_xlfn.LET( _xlpm.w, K$11, _xlpm.r, MATCH(1,('3. Enter Indicator Scores'!$B$10:$B$161=$B14)*('3. Enter Indicator Scores'!$C$10:$C$161=$C14),0), _xlpm.c, MATCH(K$8,'3. Enter Indicator Scores'!$D$8:$CZ$8,0), _xlpm.v, IFERROR(INDEX('3. Enter Indicator Scores'!$D$10:$CZ$161,_xlpm.r,_xlpm.c),""), IF(OR(_xlpm.w="",_xlpm.v=""),"",_xlpm.v*_xlpm.w) )} | ... CZ14: {=_xlfn.LET( _xlpm.w, CZ$11, _xlpm.r, MATCH(1,('3. Enter Indicator Scores'!$B$10:$B$161=$B14)*('3. Enter Indicator Scores'!$C$10:$C$161=$C14),0), _xlpm.c, MATCH(CZ$8,'3. Enter Indicator Scores'!$D$8:$CZ$8,0), _xlpm.v, IFERROR(INDEX('3. Enter Indicator Scores'!$D$10:$CZ$161,_xlpm.r,_xlpm.c),""), IF(OR(_xlpm.w="",_xlpm.v=""),"",_xlpm.v*_xlpm.w) )}
D15: {=_xlfn.LET( _xlpm.w, D$11, _xlpm.r, MATCH(1,('3. Enter Indicator Scores'!$B$10:$B$161=$B15)*('3. Enter Indicator Scores'!$C$10:$C$161=$C15),0), _xlpm.c, MATCH(D$8,'3. Enter Indicator Scores'!$D$8:$CZ$8,0), _xlpm.v, IFERROR(INDEX('3. Enter Indicator Scores'!$D$10:$CZ$161,_xlpm.r,_xlpm.c),""), IF(OR(_xlpm.w="",_xlpm.v=""),"",_xlpm.v*_xlpm.w) )} | E15: {=_xlfn.LET( _xlpm.w, E$11, _xlpm.r, MATCH(1,('3. Enter Indicator Scores'!$B$10:$B$161=$B15)*('3. Enter Indicator Scores'!$C$10:$C$161=$C15),0), _xlpm.c, MATCH(E$8,'3. Enter Indicator Scores'!$D$8:$CZ$8,0), _xlpm.v, IFERROR(INDEX('3. Enter Indicator Scores'!$D$10:$CZ$161,_xlpm.r,_xlpm.c),""), IF(OR(_xlpm.w="",_xlpm.v=""),"",_xlpm.v*_xlpm.w) )} | F15: {=_xlfn.LET( _xlpm.w, F$11, _xlpm.r, MATCH(1,('3. Enter Indicator Scores'!$B$10:$B$161=$B15)*('3. Enter Indicator Scores'!$C$10:$C$161=$C15),0), _xlpm.c, MATCH(F$8,'3. Enter Indicator Scores'!$D$8:$CZ$8,0), _xlpm.v, IFERROR(INDEX('3. Enter Indicator Scores'!$D$10:$CZ$161,_xlpm.r,_xlpm.c),""), IF(OR(_xlpm.w="",_xlpm.v=""),"",_xlpm.v*_xlpm.w) )} | G15: {=_xlfn.LET( _xlpm.w, G$11, _xlpm.r, MATCH(1,('3. Enter Indicator Scores'!$B$10:$B$161=$B15)*('3. Enter Indicator Scores'!$C$10:$C$161=$C15),0), _xlpm.c, MATCH(G$8,'3. Enter Indicator Scores'!$D$8:$CZ$8,0), _xlpm.v, IFERROR(INDEX('3. Enter Indicator Scores'!$D$10:$CZ$161,_xlpm.r,_xlpm.c),""), IF(OR(_xlpm.w="",_xlpm.v=""),"",_xlpm.v*_xlpm.w) )} | H15: {=_xlfn.LET( _xlpm.w, H$11, _xlpm.r, MATCH(1,('3. Enter Indicator Scores'!$B$10:$B$161=$B15)*('3. Enter Indicator Scores'!$C$10:$C$161=$C15),0), _xlpm.c, MATCH(H$8,'3. Enter Indicator Scores'!$D$8:$CZ$8,0), _xlpm.v, IFERROR(INDEX('3. Enter Indicator Scores'!$D$10:$CZ$161,_xlpm.r,_xlpm.c),""), IF(OR(_xlpm.w="",_xlpm.v=""),"",_xlpm.v*_xlpm.w) )} | I15: {=_xlfn.LET( _xlpm.w, I$11, _xlpm.r, MATCH(1,('3. Enter Indicator Scores'!$B$10:$B$161=$B15)*('3. Enter Indicator Scores'!$C$10:$C$161=$C15),0), _xlpm.c, MATCH(I$8,'3. Enter Indicator Scores'!$D$8:$CZ$8,0), _xlpm.v, IFERROR(INDEX('3. Enter Indicator Scores'!$D$10:$CZ$161,_xlpm.r,_xlpm.c),""), IF(OR(_xlpm.w="",_xlpm.v=""),"",_xlpm.v*_xlpm.w) )} | J15: {=_xlfn.LET( _xlpm.w, J$11, _xlpm.r, MATCH(1,('3. Enter Indicator Scores'!$B$10:$B$161=$B15)*('3. Enter Indicator Scores'!$C$10:$C$161=$C15),0), _xlpm.c, MATCH(J$8,'3. Enter Indicator Scores'!$D$8:$CZ$8,0), _xlpm.v, IFERROR(INDEX('3. Enter Indicator Scores'!$D$10:$CZ$161,_xlpm.r,_xlpm.c),""), IF(OR(_xlpm.w="",_xlpm.v=""),"",_xlpm.v*_xlpm.w) )} | K15: {=_xlfn.LET( _xlpm.w, K$11, _xlpm.r, MATCH(1,('3. Enter Indicator Scores'!$B$10:$B$161=$B15)*('3. Enter Indicator Scores'!$C$10:$C$161=$C15),0), _xlpm.c, MATCH(K$8,'3. Enter Indicator Scores'!$D$8:$CZ$8,0), _xlpm.v, IFERROR(INDEX('3. Enter Indicator Scores'!$D$10:$CZ$161,_xlpm.r,_xlpm.c),""), IF(OR(_xlpm.w="",_xlpm.v=""),"",_xlpm.v*_xlpm.w) )} | ... CZ15: {=_xlfn.LET( _xlpm.w, CZ$11, _xlpm.r, MATCH(1,('3. Enter Indicator Scores'!$B$10:$B$161=$B15)*('3. Enter Indicator Scores'!$C$10:$C$161=$C15),0), _xlpm.c, MATCH(CZ$8,'3. Enter Indicator Scores'!$D$8:$CZ$8,0), _xlpm.v, IFERROR(INDEX('3. Enter Indicator Scores'!$D$10:$CZ$161,_xlpm.r,_xlpm.c),""), IF(OR(_xlpm.w="",_xlpm.v=""),"",_xlpm.v*_xlpm.w) )}
D16: {=_xlfn.LET( _xlpm.w, D$11, _xlpm.r, MATCH(1,('3. Enter Indicator Scores'!$B$10:$B$161=$B16)*('3. Enter Indicator Scores'!$C$10:$C$161=$C16),0), _xlpm.c, MATCH(D$8,'3. Enter Indicator Scores'!$D$8:$CZ$8,0), _xlpm.v, IFERROR(INDEX('3. Enter Indicator Scores'!$D$10:$CZ$161,_xlpm.r,_xlpm.c),""), IF(OR(_xlpm.w="",_xlpm.v=""),"",_xlpm.v*_xlpm.w) )} | E16: {=_xlfn.LET( _xlpm.w, E$11, _xlpm.r, MATCH(1,('3. Enter Indicator Scores'!$B$10:$B$161=$B16)*('3. Enter Indicator Scores'!$C$10:$C$161=$C16),0), _xlpm.c, MATCH(E$8,'3. Enter Indicator Scores'!$D$8:$CZ$8,0), _xlpm.v, IFERROR(INDEX('3. Enter Indicator Scores'!$D$10:$CZ$161,_xlpm.r,_xlpm.c),""), IF(OR(_xlpm.w="",_xlpm.v=""),"",_xlpm.v*_xlpm.w) )} | F16: {=_xlfn.LET( _xlpm.w, F$11, _xlpm.r, MATCH(1,('3. Enter Indicator Scores'!$B$10:$B$161=$B16)*('3. Enter Indicator Scores'!$C$10:$C$161=$C16),0), _xlpm.c, MATCH(F$8,'3. Enter Indicator Scores'!$D$8:$CZ$8,0), _xlpm.v, IFERROR(INDEX('3. Enter Indicator Scores'!$D$10:$CZ$161,_xlpm.r,_xlpm.c),""), IF(OR(_xlpm.w="",_xlpm.v=""),"",_xlpm.v*_xlpm.w) )} | G16: {=_xlfn.LET( _xlpm.w, G$11, _xlpm.r, MATCH(1,('3. Enter Indicator Scores'!$B$10:$B$161=$B16)*('3. Enter Indicator Scores'!$C$10:$C$161=$C16),0), _xlpm.c, MATCH(G$8,'3. Enter Indicator Scores'!$D$8:$CZ$8,0), _xlpm.v, IFERROR(INDEX('3. Enter Indicator Scores'!$D$10:$CZ$161,_xlpm.r,_xlpm.c),""), IF(OR(_xlpm.w="",_xlpm.v=""),"",_xlpm.v*_xlpm.w) )} | H16: {=_xlfn.LET( _xlpm.w, H$11, _xlpm.r, MATCH(1,('3. Enter Indicator Scores'!$B$10:$B$161=$B16)*('3. Enter Indicator Scores'!$C$10:$C$161=$C16),0), _xlpm.c, MATCH(H$8,'3. Enter Indicator Scores'!$D$8:$CZ$8,0), _xlpm.v, IFERROR(INDEX('3. Enter Indicator Scores'!$D$10:$CZ$161,_xlpm.r,_xlpm.c),""), IF(OR(_xlpm.w="",_xlpm.v=""),"",_xlpm.v*_xlpm.w) )} | I16: {=_xlfn.LET( _xlpm.w, I$11, _xlpm.r, MATCH(1,('3. Enter Indicator Scores'!$B$10:$B$161=$B16)*('3. Enter Indicator Scores'!$C$10:$C$161=$C16),0), _xlpm.c, MATCH(I$8,'3. Enter Indicator Scores'!$D$8:$CZ$8,0), _xlpm.v, IFERROR(INDEX('3. Enter Indicator Scores'!$D$10:$CZ$161,_xlpm.r,_xlpm.c),""), IF(OR(_xlpm.w="",_xlpm.v=""),"",_xlpm.v*_xlpm.w) )} | J16: {=_xlfn.LET( _xlpm.w, J$11, _xlpm.r, MATCH(1,('3. Enter Indicator Scores'!$B$10:$B$161=$B16)*('3. Enter Indicator Scores'!$C$10:$C$161=$C16),0), _xlpm.c, MATCH(J$8,'3. Enter Indicator Scores'!$D$8:$CZ$8,0), _xlpm.v, IFERROR(INDEX('3. Enter Indicator Scores'!$D$10:$CZ$161,_xlpm.r,_xlpm.c),""), IF(OR(_xlpm.w="",_xlpm.v=""),"",_xlpm.v*_xlpm.w) )} | K16: {=_xlfn.LET( _xlpm.w, K$11, _xlpm.r, MATCH(1,('3. Enter Indicator Scores'!$B$10:$B$161=$B16)*('3. Enter Indicator Scores'!$C$10:$C$161=$C16),0), _xlpm.c, MATCH(K$8,'3. Enter Indicator Scores'!$D$8:$CZ$8,0), _xlpm.v, IFERROR(INDEX('3. Enter Indicator Scores'!$D$10:$CZ$161,_xlpm.r,_xlpm.c),""), IF(OR(_xlpm.w="",_xlpm.v=""),"",_xlpm.v*_xlpm.w) )} | ... CZ16: {=_xlfn.LET( _xlpm.w, CZ$11, _xlpm.r, MATCH(1,('3. Enter Indicator Scores'!$B$10:$B$161=$B16)*('3. Enter Indicator Scores'!$C$10:$C$161=$C16),0), _xlpm.c, MATCH(CZ$8,'3. Enter Indicator Scores'!$D$8:$CZ$8,0), _xlpm.v, IFERROR(INDEX('3. Enter Indicator Scores'!$D$10:$CZ$161,_xlpm.r,_xlpm.c),""), IF(OR(_xlpm.w="",_xlpm.v=""),"",_xlpm.v*_xlpm.w) )}
D17: {=_xlfn.LET( _xlpm.w, D$11, _xlpm.r, MATCH(1,('3. Enter Indicator Scores'!$B$10:$B$161=$B17)*('3. Enter Indicator Scores'!$C$10:$C$161=$C17),0), _xlpm.c, MATCH(D$8,'3. Enter Indicator Scores'!$D$8:$CZ$8,0), _xlpm.v, IFERROR(INDEX('3. Enter Indicator Scores'!$D$10:$CZ$161,_xlpm.r,_xlpm.c),""), IF(OR(_xlpm.w="",_xlpm.v=""),"",_xlpm.v*_xlpm.w) )} | E17: {=_xlfn.LET( _xlpm.w, E$11, _xlpm.r, MATCH(1,('3. Enter Indicator Scores'!$B$10:$B$161=$B17)*('3. Enter Indicator Scores'!$C$10:$C$161=$C17),0), _xlpm.c, MATCH(E$8,'3. Enter Indicator Scores'!$D$8:$CZ$8,0), _xlpm.v, IFERROR(INDEX('3. Enter Indicator Scores'!$D$10:$CZ$161,_xlpm.r,_xlpm.c),""), IF(OR(_xlpm.w="",_xlpm.v=""),"",_xlpm.v*_xlpm.w) )} | F17: {=_xlfn.LET( _xlpm.w, F$11, _xlpm.r, MATCH(1,('3. Enter Indicator Scores'!$B$10:$B$161=$B17)*('3. Enter Indicator Scores'!$C$10:$C$161=$C17),0), _xlpm.c, MATCH(F$8,'3. Enter Indicator Scores'!$D$8:$CZ$8,0), _xlpm.v, IFERROR(INDEX('3. Enter Indicator Scores'!$D$10:$CZ$161,_xlpm.r,_xlpm.c),""), IF(OR(_xlpm.w="",_xlpm.v=""),"",_xlpm.v*_xlpm.w) )} | G17: {=_xlfn.LET( _xlpm.w, G$11, _xlpm.r, MATCH(1,('3. Enter Indicator Scores'!$B$10:$B$161=$B17)*('3. Enter Indicator Scores'!$C$10:$C$161=$C17),0), _xlpm.c, MATCH(G$8,'3. Enter Indicator Scores'!$D$8:$CZ$8,0), _xlpm.v, IFERROR(INDEX('3. Enter Indicator Scores'!$D$10:$CZ$161,_xlpm.r,_xlpm.c),""), IF(OR(_xlpm.w="",_xlpm.v=""),"",_xlpm.v*_xlpm.w) )} | H17: {=_xlfn.LET( _xlpm.w, H$11, _xlpm.r, MATCH(1,('3. Enter Indicator Scores'!$B$10:$B$161=$B17)*('3. Enter Indicator Scores'!$C$10:$C$161=$C17),0), _xlpm.c, MATCH(H$8,'3. Enter Indicator Scores'!$D$8:$CZ$8,0), _xlpm.v, IFERROR(INDEX('3. Enter Indicator Scores'!$D$10:$CZ$161,_xlpm.r,_xlpm.c),""), IF(OR(_xlpm.w="",_xlpm.v=""),"",_xlpm.v*_xlpm.w) )} | I17: {=_xlfn.LET( _xlpm.w, I$11, _xlpm.r, MATCH(1,('3. Enter Indicator Scores'!$B$10:$B$161=$B17)*('3. Enter Indicator Scores'!$C$10:$C$161=$C17),0), _xlpm.c, MATCH(I$8,'3. Enter Indicator Scores'!$D$8:$CZ$8,0), _xlpm.v, IFERROR(INDEX('3. Enter Indicator Scores'!$D$10:$CZ$161,_xlpm.r,_xlpm.c),""), IF(OR(_xlpm.w="",_xlpm.v=""),"",_xlpm.v*_xlpm.w) )} | J17: {=_xlfn.LET( _xlpm.w, J$11, _xlpm.r, MATCH(1,('3. Enter Indicator Scores'!$B$10:$B$161=$B17)*('3. Enter Indicator Scores'!$C$10:$C$161=$C17),0), _xlpm.c, MATCH(J$8,'3. Enter Indicator Scores'!$D$8:$CZ$8,0), _xlpm.v, IFERROR(INDEX('3. Enter Indicator Scores'!$D$10:$CZ$161,_xlpm.r,_xlpm.c),""), IF(OR(_xlpm.w="",_xlpm.v=""),"",_xlpm.v*_xlpm.w) )} | K17: {=_xlfn.LET( _xlpm.w, K$11, _xlpm.r, MATCH(1,('3. Enter Indicator Scores'!$B$10:$B$161=$B17)*('3. Enter Indicator Scores'!$C$10:$C$161=$C17),0), _xlpm.c, MATCH(K$8,'3. Enter Indicator Scores'!$D$8:$CZ$8,0), _xlpm.v, IFERROR(INDEX('3. Enter Indicator Scores'!$D$10:$CZ$161,_xlpm.r,_xlpm.c),""), IF(OR(_xlpm.w="",_xlpm.v=""),"",_xlpm.v*_xlpm.w) )} | ... CZ17: {=_xlfn.LET( _xlpm.w, CZ$11, _xlpm.r, MATCH(1,('3. Enter Indicator Scores'!$B$10:$B$161=$B17)*('3. Enter Indicator Scores'!$C$10:$C$161=$C17),0), _xlpm.c, MATCH(CZ$8,'3. Enter Indicator Scores'!$D$8:$CZ$8,0), _xlpm.v, IFERROR(INDEX('3. Enter Indicator Scores'!$D$10:$CZ$161,_xlpm.r,_xlpm.c),""), IF(OR(_xlpm.w="",_xlpm.v=""),"",_xlpm.v*_xlpm.w) )}
D18: {=_xlfn.LET( _xlpm.w, D$11, _xlpm.r, MATCH(1,('3. Enter Indicator Scores'!$B$10:$B$161=$B18)*('3. Enter Indicator Scores'!$C$10:$C$161=$C18),0), _xlpm.c, MATCH(D$8,'3. Enter Indicator Scores'!$D$8:$CZ$8,0), _xlpm.v, IFERROR(INDEX('3. Enter Indicator Scores'!$D$10:$CZ$161,_xlpm.r,_xlpm.c),""), IF(OR(_xlpm.w="",_xlpm.v=""),"",_xlpm.v*_xlpm.w) )} | E18: {=_xlfn.LET( _xlpm.w, E$11, _xlpm.r, MATCH(1,('3. Enter Indicator Scores'!$B$10:$B$161=$B18)*('3. Enter Indicator Scores'!$C$10:$C$161=$C18),0), _xlpm.c, MATCH(E$8,'3. Enter Indicator Scores'!$D$8:$CZ$8,0), _xlpm.v, IFERROR(INDEX('3. Enter Indicator Scores'!$D$10:$CZ$161,_xlpm.r,_xlpm.c),""), IF(OR(_xlpm.w="",_xlpm.v=""),"",_xlpm.v*_xlpm.w) )} | F18: {=_xlfn.LET( _xlpm.w, F$11, _xlpm.r, MATCH(1,('3. Enter Indicator Scores'!$B$10:$B$161=$B18)*('3. Enter Indicator Scores'!$C$10:$C$161=$C18),0), _xlpm.c, MATCH(F$8,'3. Enter Indicator Scores'!$D$8:$CZ$8,0), _xlpm.v, IFERROR(INDEX('3. Enter Indicator Scores'!$D$10:$CZ$161,_xlpm.r,_xlpm.c),""), IF(OR(_xlpm.w="",_xlpm.v=""),"",_xlpm.v*_xlpm.w) )} | G18: {=_xlfn.LET( _xlpm.w, G$11, _xlpm.r, MATCH(1,('3. Enter Indicator Scores'!$B$10:$B$161=$B18)*('3. Enter Indicator Scores'!$C$10:$C$161=$C18),0), _xlpm.c, MATCH(G$8,'3. Enter Indicator Scores'!$D$8:$CZ$8,0), _xlpm.v, IFERROR(INDEX('3. Enter Indicator Scores'!$D$10:$CZ$161,_xlpm.r,_xlpm.c),""), IF(OR(_xlpm.w="",_xlpm.v=""),"",_xlpm.v*_xlpm.w) )} | H18: {=_xlfn.LET( _xlpm.w, H$11, _xlpm.r, MATCH(1,('3. Enter Indicator Scores'!$B$10:$B$161=$B18)*('3. Enter Indicator Scores'!$C$10:$C$161=$C18),0), _xlpm.c, MATCH(H$8,'3. Enter Indicator Scores'!$D$8:$CZ$8,0), _xlpm.v, IFERROR(INDEX('3. Enter Indicator Scores'!$D$10:$CZ$161,_xlpm.r,_xlpm.c),""), IF(OR(_xlpm.w="",_xlpm.v=""),"",_xlpm.v*_xlpm.w) )} | I18: {=_xlfn.LET( _xlpm.w, I$11, _xlpm.r, MATCH(1,('3. Enter Indicator Scores'!$B$10:$B$161=$B18)*('3. Enter Indicator Scores'!$C$10:$C$161=$C18),0), _xlpm.c, MATCH(I$8,'3. Enter Indicator Scores'!$D$8:$CZ$8,0), _xlpm.v, IFERROR(INDEX('3. Enter Indicator Scores'!$D$10:$CZ$161,_xlpm.r,_xlpm.c),""), IF(OR(_xlpm.w="",_xlpm.v=""),"",_xlpm.v*_xlpm.w) )} | J18: {=_xlfn.LET( _xlpm.w, J$11, _xlpm.r, MATCH(1,('3. Enter Indicator Scores'!$B$10:$B$161=$B18)*('3. Enter Indicator Scores'!$C$10:$C$161=$C18),0), _xlpm.c, MATCH(J$8,'3. Enter Indicator Scores'!$D$8:$CZ$8,0), _xlpm.v, IFERROR(INDEX('3. Enter Indicator Scores'!$D$10:$CZ$161,_xlpm.r,_xlpm.c),""), IF(OR(_xlpm.w="",_xlpm.v=""),"",_xlpm.v*_xlpm.w) )} | K18: {=_xlfn.LET( _xlpm.w, K$11, _xlpm.r, MATCH(1,('3. Enter Indicator Scores'!$B$10:$B$161=$B18)*('3. Enter Indicator Scores'!$C$10:$C$161=$C18),0), _xlpm.c, MATCH(K$8,'3. Enter Indicator Scores'!$D$8:$CZ$8,0), _xlpm.v, IFERROR(INDEX('3. Enter Indicator Scores'!$D$10:$CZ$161,_xlpm.r,_xlpm.c),""), IF(OR(_xlpm.w="",_xlpm.v=""),"",_xlpm.v*_xlpm.w) )} | ... CZ18: {=_xlfn.LET( _xlpm.w, CZ$11, _xlpm.r, MATCH(1,('3. Enter Indicator Scores'!$B$10:$B$161=$B18)*('3. Enter Indicator Scores'!$C$10:$C$161=$C18),0), _xlpm.c, MATCH(CZ$8,'3. Enter Indicator Scores'!$D$8:$CZ$8,0), _xlpm.v, IFERROR(INDEX('3. Enter Indicator Scores'!$D$10:$CZ$161,_xlpm.r,_xlpm.c),""), IF(OR(_xlpm.w="",_xlpm.v=""),"",_xlpm.v*_xlpm.w) )}
D19: {=_xlfn.LET( _xlpm.w, D$11, _xlpm.r, MATCH(1,('3. Enter Indicator Scores'!$B$10:$B$161=$B19)*('3. Enter Indicator Scores'!$C$10:$C$161=$C19),0), _xlpm.c, MATCH(D$8,'3. Enter Indicator Scores'!$D$8:$CZ$8,0), _xlpm.v, IFERROR(INDEX('3. Enter Indicator Scores'!$D$10:$CZ$161,_xlpm.r,_xlpm.c),""), IF(OR(_xlpm.w="",_xlpm.v=""),"",_xlpm.v*_xlpm.w) )} | E19: {=_xlfn.LET( _xlpm.w, E$11, _xlpm.r, MATCH(1,('3. Enter Indicator Scores'!$B$10:$B$161=$B19)*('3. Enter Indicator Scores'!$C$10:$C$161=$C19),0), _xlpm.c, MATCH(E$8,'3. Enter Indicator Scores'!$D$8:$CZ$8,0), _xlpm.v, IFERROR(INDEX('3. Enter Indicator Scores'!$D$10:$CZ$161,_xlpm.r,_xlpm.c),""), IF(OR(_xlpm.w="",_xlpm.v=""),"",_xlpm.v*_xlpm.w) )} | F19: {=_xlfn.LET( _xlpm.w, F$11, _xlpm.r, MATCH(1,('3. Enter Indicator Scores'!$B$10:$B$161=$B19)*('3. Enter Indicator Scores'!$C$10:$C$161=$C19),0), _xlpm.c, MATCH(F$8,'3. Enter Indicator Scores'!$D$8:$CZ$8,0), _xlpm.v, IFERROR(INDEX('3. Enter Indicator Scores'!$D$10:$CZ$161,_xlpm.r,_xlpm.c),""), IF(OR(_xlpm.w="",_xlpm.v=""),"",_xlpm.v*_xlpm.w) )} | G19: {=_xlfn.LET( _xlpm.w, G$11, _xlpm.r, MATCH(1,('3. Enter Indicator Scores'!$B$10:$B$161=$B19)*('3. Enter Indicator Scores'!$C$10:$C$161=$C19),0), _xlpm.c, MATCH(G$8,'3. Enter Indicator Scores'!$D$8:$CZ$8,0), _xlpm.v, IFERROR(INDEX('3. Enter Indicator Scores'!$D$10:$CZ$161,_xlpm.r,_xlpm.c),""), IF(OR(_xlpm.w="",_xlpm.v=""),"",_xlpm.v*_xlpm.w) )} | H19: {=_xlfn.LET( _xlpm.w, H$11, _xlpm.r, MATCH(1,('3. Enter Indicator Scores'!$B$10:$B$161=$B19)*('3. Enter Indicator Scores'!$C$10:$C$161=$C19),0), _xlpm.c, MATCH(H$8,'3. Enter Indicator Scores'!$D$8:$CZ$8,0), _xlpm.v, IFERROR(INDEX('3. Enter Indicator Scores'!$D$10:$CZ$161,_xlpm.r,_xlpm.c),""), IF(OR(_xlpm.w="",_xlpm.v=""),"",_xlpm.v*_xlpm.w) )} | I19: {=_xlfn.LET( _xlpm.w, I$11, _xlpm.r, MATCH(1,('3. Enter Indicator Scores'!$B$10:$B$161=$B19)*('3. Enter Indicator Scores'!$C$10:$C$161=$C19),0), _xlpm.c, MATCH(I$8,'3. Enter Indicator Scores'!$D$8:$CZ$8,0), _xlpm.v, IFERROR(INDEX('3. Enter Indicator Scores'!$D$10:$CZ$161,_xlpm.r,_xlpm.c),""), IF(OR(_xlpm.w="",_xlpm.v=""),"",_xlpm.v*_xlpm.w) )} | J19: {=_xlfn.LET( _xlpm.w, J$11, _xlpm.r, MATCH(1,('3. Enter Indicator Scores'!$B$10:$B$161=$B19)*('3. Enter Indicator Scores'!$C$10:$C$161=$C19),0), _xlpm.c, MATCH(J$8,'3. Enter Indicator Scores'!$D$8:$CZ$8,0), _xlpm.v, IFERROR(INDEX('3. Enter Indicator Scores'!$D$10:$CZ$161,_xlpm.r,_xlpm.c),""), IF(OR(_xlpm.w="",_xlpm.v=""),"",_xlpm.v*_xlpm.w) )} | K19: {=_xlfn.LET( _xlpm.w, K$11, _xlpm.r, MATCH(1,('3. Enter Indicator Scores'!$B$10:$B$161=$B19)*('3. Enter Indicator Scores'!$C$10:$C$161=$C19),0), _xlpm.c, MATCH(K$8,'3. Enter Indicator Scores'!$D$8:$CZ$8,0), _xlpm.v, IFERROR(INDEX('3. Enter Indicator Scores'!$D$10:$CZ$161,_xlpm.r,_xlpm.c),""), IF(OR(_xlpm.w="",_xlpm.v=""),"",_xlpm.v*_xlpm.w) )} | ... CZ19: {=_xlfn.LET( _xlpm.w, CZ$11, _xlpm.r, MATCH(1,('3. Enter Indicator Scores'!$B$10:$B$161=$B19)*('3. Enter Indicator Scores'!$C$10:$C$161=$C19),0), _xlpm.c, MATCH(CZ$8,'3. Enter Indicator Scores'!$D$8:$CZ$8,0), _xlpm.v, IFERROR(INDEX('3. Enter Indicator Scores'!$D$10:$CZ$161,_xlpm.r,_xlpm.c),""), IF(OR(_xlpm.w="",_xlpm.v=""),"",_xlpm.v*_xlpm.w) )}
D20: {=_xlfn.LET( _xlpm.w, D$11, _xlpm.r, MATCH(1,('3. Enter Indicator Scores'!$B$10:$B$161=$B20)*('3. Enter Indicator Scores'!$C$10:$C$161=$C20),0), _xlpm.c, MATCH(D$8,'3. Enter Indicator Scores'!$D$8:$CZ$8,0), _xlpm.v, IFERROR(INDEX('3. Enter Indicator Scores'!$D$10:$CZ$161,_xlpm.r,_xlpm.c),""), IF(OR(_xlpm.w="",_xlpm.v=""),"",_xlpm.v*_xlpm.w) )} | E20: {=_xlfn.LET( _xlpm.w, E$11, _xlpm.r, MATCH(1,('3. Enter Indicator Scores'!$B$10:$B$161=$B20)*('3. Enter Indicator Scores'!$C$10:$C$161=$C20),0), _xlpm.c, MATCH(E$8,'3. Enter Indicator Scores'!$D$8:$CZ$8,0), _xlpm.v, IFERROR(INDEX('3. Enter Indicator Scores'!$D$10:$CZ$161,_xlpm.r,_xlpm.c),""), IF(OR(_xlpm.w="",_xlpm.v=""),"",_xlpm.v*_xlpm.w) )} | F20: {=_xlfn.LET( _xlpm.w, F$11, _xlpm.r, MATCH(1,('3. Enter Indicator Scores'!$B$10:$B$161=$B20)*('3. Enter Indicator Scores'!$C$10:$C$161=$C20),0), _xlpm.c, MATCH(F$8,'3. Enter Indicator Scores'!$D$8:$CZ$8,0), _xlpm.v, IFERROR(INDEX('3. Enter Indicator Scores'!$D$10:$CZ$161,_xlpm.r,_xlpm.c),""), IF(OR(_xlpm.w="",_xlpm.v=""),"",_xlpm.v*_xlpm.w) )} | G20: {=_xlfn.LET( _xlpm.w, G$11, _xlpm.r, MATCH(1,('3. Enter Indicator Scores'!$B$10:$B$161=$B20)*('3. Enter Indicator Scores'!$C$10:$C$161=$C20),0), _xlpm.c, MATCH(G$8,'3. Enter Indicator Scores'!$D$8:$CZ$8,0), _xlpm.v, IFERROR(INDEX('3. Enter Indicator Scores'!$D$10:$CZ$161,_xlpm.r,_xlpm.c),""), IF(OR(_xlpm.w="",_xlpm.v=""),"",_xlpm.v*_xlpm.w) )} | H20: {=_xlfn.LET( _xlpm.w, H$11, _xlpm.r, MATCH(1,('3. Enter Indicator Scores'!$B$10:$B$161=$B20)*('3. Enter Indicator Scores'!$C$10:$C$161=$C20),0), _xlpm.c, MATCH(H$8,'3. Enter Indicator Scores'!$D$8:$CZ$8,0), _xlpm.v, IFERROR(INDEX('3. Enter Indicator Scores'!$D$10:$CZ$161,_xlpm.r,_xlpm.c),""), IF(OR(_xlpm.w="",_xlpm.v=""),"",_xlpm.v*_xlpm.w) )} | I20: {=_xlfn.LET( _xlpm.w, I$11, _xlpm.r, MATCH(1,('3. Enter Indicator Scores'!$B$10:$B$161=$B20)*('3. Enter Indicator Scores'!$C$10:$C$161=$C20),0), _xlpm.c, MATCH(I$8,'3. Enter Indicator Scores'!$D$8:$CZ$8,0), _xlpm.v, IFERROR(INDEX('3. Enter Indicator Scores'!$D$10:$CZ$161,_xlpm.r,_xlpm.c),""), IF(OR(_xlpm.w="",_xlpm.v=""),"",_xlpm.v*_xlpm.w) )} | J20: {=_xlfn.LET( _xlpm.w, J$11, _xlpm.r, MATCH(1,('3. Enter Indicator Scores'!$B$10:$B$161=$B20)*('3. Enter Indicator Scores'!$C$10:$C$161=$C20),0), _xlpm.c, MATCH(J$8,'3. Enter Indicator Scores'!$D$8:$CZ$8,0), _xlpm.v, IFERROR(INDEX('3. Enter Indicator Scores'!$D$10:$CZ$161,_xlpm.r,_xlpm.c),""), IF(OR(_xlpm.w="",_xlpm.v=""),"",_xlpm.v*_xlpm.w) )} | K20: {=_xlfn.LET( _xlpm.w, K$11, _xlpm.r, MATCH(1,('3. Enter Indicator Scores'!$B$10:$B$161=$B20)*('3. Enter Indicator Scores'!$C$10:$C$161=$C20),0), _xlpm.c, MATCH(K$8,'3. Enter Indicator Scores'!$D$8:$CZ$8,0), _xlpm.v, IFERROR(INDEX('3. Enter Indicator Scores'!$D$10:$CZ$161,_xlpm.r,_xlpm.c),""), IF(OR(_xlpm.w="",_xlpm.v=""),"",_xlpm.v*_xlpm.w) )} | ... CZ20: {=_xlfn.LET( _xlpm.w, CZ$11, _xlpm.r, MATCH(1,('3. Enter Indicator Scores'!$B$10:$B$161=$B20)*('3. Enter Indicator Scores'!$C$10:$C$161=$C20),0), _xlpm.c, MATCH(CZ$8,'3. Enter Indicator Scores'!$D$8:$CZ$8,0), _xlpm.v, IFERROR(INDEX('3. Enter Indicator Scores'!$D$10:$CZ$161,_xlpm.r,_xlpm.c),""), IF(OR(_xlpm.w="",_xlpm.v=""),"",_xlpm.v*_xlpm.w) )}
D21: {=_xlfn.LET( _xlpm.w, D$11, _xlpm.r, MATCH(1,('3. Enter Indicator Scores'!$B$10:$B$161=$B21)*('3. Enter Indicator Scores'!$C$10:$C$161=$C21),0), _xlpm.c, MATCH(D$8,'3. Enter Indicator Scores'!$D$8:$CZ$8,0), _xlpm.v, IFERROR(INDEX('3. Enter Indicator Scores'!$D$10:$CZ$161,_xlpm.r,_xlpm.c),""), IF(OR(_xlpm.w="",_xlpm.v=""),"",_xlpm.v*_xlpm.w) )} | E21: {=_xlfn.LET( _xlpm.w, E$11, _xlpm.r, MATCH(1,('3. Enter Indicator Scores'!$B$10:$B$161=$B21)*('3. Enter Indicator Scores'!$C$10:$C$161=$C21),0), _xlpm.c, MATCH(E$8,'3. Enter Indicator Scores'!$D$8:$CZ$8,0), _xlpm.v, IFERROR(INDEX('3. Enter Indicator Scores'!$D$10:$CZ$161,_xlpm.r,_xlpm.c),""), IF(OR(_xlpm.w="",_xlpm.v=""),"",_xlpm.v*_xlpm.w) )} | F21: {=_xlfn.LET( _xlpm.w, F$11, _xlpm.r, MATCH(1,('3. Enter Indicator Scores'!$B$10:$B$161=$B21)*('3. Enter Indicator Scores'!$C$10:$C$161=$C21),0), _xlpm.c, MATCH(F$8,'3. Enter Indicator Scores'!$D$8:$CZ$8,0), _xlpm.v, IFERROR(INDEX('3. Enter Indicator Scores'!$D$10:$CZ$161,_xlpm.r,_xlpm.c),""), IF(OR(_xlpm.w="",_xlpm.v=""),"",_xlpm.v*_xlpm.w) )} | G21: {=_xlfn.LET( _xlpm.w, G$11, _xlpm.r, MATCH(1,('3. Enter Indicator Scores'!$B$10:$B$161=$B21)*('3. Enter Indicator Scores'!$C$10:$C$161=$C21),0), _xlpm.c, MATCH(G$8,'3. Enter Indicator Scores'!$D$8:$CZ$8,0), _xlpm.v, IFERROR(INDEX('3. Enter Indicator Scores'!$D$10:$CZ$161,_xlpm.r,_xlpm.c),""), IF(OR(_xlpm.w="",_xlpm.v=""),"",_xlpm.v*_xlpm.w) )} | H21: {=_xlfn.LET( _xlpm.w, H$11, _xlpm.r, MATCH(1,('3. Enter Indicator Scores'!$B$10:$B$161=$B21)*('3. Enter Indicator Scores'!$C$10:$C$161=$C21),0), _xlpm.c, MATCH(H$8,'3. Enter Indicator Scores'!$D$8:$CZ$8,0), _xlpm.v, IFERROR(INDEX('3. Enter Indicator Scores'!$D$10:$CZ$161,_xlpm.r,_xlpm.c),""), IF(OR(_xlpm.w="",_xlpm.v=""),"",_xlpm.v*_xlpm.w) )} | I21: {=_xlfn.LET( _xlpm.w, I$11, _xlpm.r, MATCH(1,('3. Enter Indicator Scores'!$B$10:$B$161=$B21)*('3. Enter Indicator Scores'!$C$10:$C$161=$C21),0), _xlpm.c, MATCH(I$8,'3. Enter Indicator Scores'!$D$8:$CZ$8,0), _xlpm.v, IFERROR(INDEX('3. Enter Indicator Scores'!$D$10:$CZ$161,_xlpm.r,_xlpm.c),""), IF(OR(_xlpm.w="",_xlpm.v=""),"",_xlpm.v*_xlpm.w) )} | J21: {=_xlfn.LET( _xlpm.w, J$11, _xlpm.r, MATCH(1,('3. Enter Indicator Scores'!$B$10:$B$161=$B21)*('3. Enter Indicator Scores'!$C$10:$C$161=$C21),0), _xlpm.c, MATCH(J$8,'3. Enter Indicator Scores'!$D$8:$CZ$8,0), _xlpm.v, IFERROR(INDEX('3. Enter Indicator Scores'!$D$10:$CZ$161,_xlpm.r,_xlpm.c),""), IF(OR(_xlpm.w="",_xlpm.v=""),"",_xlpm.v*_xlpm.w) )} | K21: {=_xlfn.LET( _xlpm.w, K$11, _xlpm.r, MATCH(1,('3. Enter Indicator Scores'!$B$10:$B$161=$B21)*('3. Enter Indicator Scores'!$C$10:$C$161=$C21),0), _xlpm.c, MATCH(K$8,'3. Enter Indicator Scores'!$D$8:$CZ$8,0), _xlpm.v, IFERROR(INDEX('3. Enter Indicator Scores'!$D$10:$CZ$161,_xlpm.r,_xlpm.c),""), IF(OR(_xlpm.w="",_xlpm.v=""),"",_xlpm.v*_xlpm.w) )} | ... CZ21: {=_xlfn.LET( _xlpm.w, CZ$11, _xlpm.r, MATCH(1,('3. Enter Indicator Scores'!$B$10:$B$161=$B21)*('3. Enter Indicator Scores'!$C$10:$C$161=$C21),0), _xlpm.c, MATCH(CZ$8,'3. Enter Indicator Scores'!$D$8:$CZ$8,0), _xlpm.v, IFERROR(INDEX('3. Enter Indicator Scores'!$D$10:$CZ$161,_xlpm.r,_xlpm.c),""), IF(OR(_xlpm.w="",_xlpm.v=""),"",_xlpm.v*_xlpm.w) )}
D22: {=_xlfn.LET( _xlpm.w, D$11, _xlpm.r, MATCH(1,('3. Enter Indicator Scores'!$B$10:$B$161=$B22)*('3. Enter Indicator Scores'!$C$10:$C$161=$C22),0), _xlpm.c, MATCH(D$8,'3. Enter Indicator Scores'!$D$8:$CZ$8,0), _xlpm.v, IFERROR(INDEX('3. Enter Indicator Scores'!$D$10:$CZ$161,_xlpm.r,_xlpm.c),""), IF(OR(_xlpm.w="",_xlpm.v=""),"",_xlpm.v*_xlpm.w) )} | E22: {=_xlfn.LET( _xlpm.w, E$11, _xlpm.r, MATCH(1,('3. Enter Indicator Scores'!$B$10:$B$161=$B22)*('3. Enter Indicator Scores'!$C$10:$C$161=$C22),0), _xlpm.c, MATCH(E$8,'3. Enter Indicator Scores'!$D$8:$CZ$8,0), _xlpm.v, IFERROR(INDEX('3. Enter Indicator Scores'!$D$10:$CZ$161,_xlpm.r,_xlpm.c),""), IF(OR(_xlpm.w="",_xlpm.v=""),"",_xlpm.v*_xlpm.w) )} | F22: {=_xlfn.LET( _xlpm.w, F$11, _xlpm.r, MATCH(1,('3. Enter Indicator Scores'!$B$10:$B$161=$B22)*('3. Enter Indicator Scores'!$C$10:$C$161=$C22),0), _xlpm.c, MATCH(F$8,'3. Enter Indicator Scores'!$D$8:$CZ$8,0), _xlpm.v, IFERROR(INDEX('3. Enter Indicator Scores'!$D$10:$CZ$161,_xlpm.r,_xlpm.c),""), IF(OR(_xlpm.w="",_xlpm.v=""),"",_xlpm.v*_xlpm.w) )} | G22: {=_xlfn.LET( _xlpm.w, G$11, _xlpm.r, MATCH(1,('3. Enter Indicator Scores'!$B$10:$B$161=$B22)*('3. Enter Indicator Scores'!$C$10:$C$161=$C22),0), _xlpm.c, MATCH(G$8,'3. Enter Indicator Scores'!$D$8:$CZ$8,0), _xlpm.v, IFERROR(INDEX('3. Enter Indicator Scores'!$D$10:$CZ$161,_xlpm.r,_xlpm.c),""), IF(OR(_xlpm.w="",_xlpm.v=""),"",_xlpm.v*_xlpm.w) )} | H22: {=_xlfn.LET( _xlpm.w, H$11, _xlpm.r, MATCH(1,('3. Enter Indicator Scores'!$B$10:$B$161=$B22)*('3. Enter Indicator Scores'!$C$10:$C$161=$C22),0), _xlpm.c, MATCH(H$8,'3. Enter Indicator Scores'!$D$8:$CZ$8,0), _xlpm.v, IFERROR(INDEX('3. Enter Indicator Scores'!$D$10:$CZ$161,_xlpm.r,_xlpm.c),""), IF(OR(_xlpm.w="",_xlpm.v=""),"",_xlpm.v*_xlpm.w) )} | I22: {=_xlfn.LET( _xlpm.w, I$11, _xlpm.r, MATCH(1,('3. Enter Indicator Scores'!$B$10:$B$161=$B22)*('3. Enter Indicator Scores'!$C$10:$C$161=$C22),0), _xlpm.c, MATCH(I$8,'3. Enter Indicator Scores'!$D$8:$CZ$8,0), _xlpm.v, IFERROR(INDEX('3. Enter Indicator Scores'!$D$10:$CZ$161,_xlpm.r,_xlpm.c),""), IF(OR(_xlpm.w="",_xlpm.v=""),"",_xlpm.v*_xlpm.w) )} | J22: {=_xlfn.LET( _xlpm.w, J$11, _xlpm.r, MATCH(1,('3. Enter Indicator Scores'!$B$10:$B$161=$B22)*('3. Enter Indicator Scores'!$C$10:$C$161=$C22),0), _xlpm.c, MATCH(J$8,'3. Enter Indicator Scores'!$D$8:$CZ$8,0), _xlpm.v, IFERROR(INDEX('3. Enter Indicator Scores'!$D$10:$CZ$161,_xlpm.r,_xlpm.c),""), IF(OR(_xlpm.w="",_xlpm.v=""),"",_xlpm.v*_xlpm.w) )} | K22: {=_xlfn.LET( _xlpm.w, K$11, _xlpm.r, MATCH(1,('3. Enter Indicator Scores'!$B$10:$B$161=$B22)*('3. Enter Indicator Scores'!$C$10:$C$161=$C22),0), _xlpm.c, MATCH(K$8,'3. Enter Indicator Scores'!$D$8:$CZ$8,0), _xlpm.v, IFERROR(INDEX('3. Enter Indicator Scores'!$D$10:$CZ$161,_xlpm.r,_xlpm.c),""), IF(OR(_xlpm.w="",_xlpm.v=""),"",_xlpm.v*_xlpm.w) )} | ... CZ22: {=_xlfn.LET( _xlpm.w, CZ$11, _xlpm.r, MATCH(1,('3. Enter Indicator Scores'!$B$10:$B$161=$B22)*('3. Enter Indicator Scores'!$C$10:$C$161=$C22),0), _xlpm.c, MATCH(CZ$8,'3. Enter Indicator Scores'!$D$8:$CZ$8,0), _xlpm.v, IFERROR(INDEX('3. Enter Indicator Scores'!$D$10:$CZ$161,_xlpm.r,_xlpm.c),""), IF(OR(_xlpm.w="",_xlpm.v=""),"",_xlpm.v*_xlpm.w) )}
D23: {=_xlfn.LET( _xlpm.w, D$11, _xlpm.r, MATCH(1,('3. Enter Indicator Scores'!$B$10:$B$161=$B23)*('3. Enter Indicator Scores'!$C$10:$C$161=$C23),0), _xlpm.c, MATCH(D$8,'3. Enter Indicator Scores'!$D$8:$CZ$8,0), _xlpm.v, IFERROR(INDEX('3. Enter Indicator Scores'!$D$10:$CZ$161,_xlpm.r,_xlpm.c),""), IF(OR(_xlpm.w="",_xlpm.v=""),"",_xlpm.v*_xlpm.w) )} | E23: {=_xlfn.LET( _xlpm.w, E$11, _xlpm.r, MATCH(1,('3. Enter Indicator Scores'!$B$10:$B$161=$B23)*('3. Enter Indicator Scores'!$C$10:$C$161=$C23),0), _xlpm.c, MATCH(E$8,'3. Enter Indicator Scores'!$D$8:$CZ$8,0), _xlpm.v, IFERROR(INDEX('3. Enter Indicator Scores'!$D$10:$CZ$161,_xlpm.r,_xlpm.c),""), IF(OR(_xlpm.w="",_xlpm.v=""),"",_xlpm.v*_xlpm.w) )} | F23: {=_xlfn.LET( _xlpm.w, F$11, _xlpm.r, MATCH(1,('3. Enter Indicator Scores'!$B$10:$B$161=$B23)*('3. Enter Indicator Scores'!$C$10:$C$161=$C23),0), _xlpm.c, MATCH(F$8,'3. Enter Indicator Scores'!$D$8:$CZ$8,0), _xlpm.v, IFERROR(INDEX('3. Enter Indicator Scores'!$D$10:$CZ$161,_xlpm.r,_xlpm.c),""), IF(OR(_xlpm.w="",_xlpm.v=""),"",_xlpm.v*_xlpm.w) )} | G23: {=_xlfn.LET( _xlpm.w, G$11, _xlpm.r, MATCH(1,('3. Enter Indicator Scores'!$B$10:$B$161=$B23)*('3. Enter Indicator Scores'!$C$10:$C$161=$C23),0), _xlpm.c, MATCH(G$8,'3. Enter Indicator Scores'!$D$8:$CZ$8,0), _xlpm.v, IFERROR(INDEX('3. Enter Indicator Scores'!$D$10:$CZ$161,_xlpm.r,_xlpm.c),""), IF(OR(_xlpm.w="",_xlpm.v=""),"",_xlpm.v*_xlpm.w) )} | H23: {=_xlfn.LET( _xlpm.w, H$11, _xlpm.r, MATCH(1,('3. Enter Indicator Scores'!$B$10:$B$161=$B23)*('3. Enter Indicator Scores'!$C$10:$C$161=$C23),0), _xlpm.c, MATCH(H$8,'3. Enter Indicator Scores'!$D$8:$CZ$8,0), _xlpm.v, IFERROR(INDEX('3. Enter Indicator Scores'!$D$10:$CZ$161,_xlpm.r,_xlpm.c),""), IF(OR(_xlpm.w="",_xlpm.v=""),"",_xlpm.v*_xlpm.w) )} | I23: {=_xlfn.LET( _xlpm.w, I$11, _xlpm.r, MATCH(1,('3. Enter Indicator Scores'!$B$10:$B$161=$B23)*('3. Enter Indicator Scores'!$C$10:$C$161=$C23),0), _xlpm.c, MATCH(I$8,'3. Enter Indicator Scores'!$D$8:$CZ$8,0), _xlpm.v, IFERROR(INDEX('3. Enter Indicator Scores'!$D$10:$CZ$161,_xlpm.r,_xlpm.c),""), IF(OR(_xlpm.w="",_xlpm.v=""),"",_xlpm.v*_xlpm.w) )} | J23: {=_xlfn.LET( _xlpm.w, J$11, _xlpm.r, MATCH(1,('3. Enter Indicator Scores'!$B$10:$B$161=$B23)*('3. Enter Indicator Scores'!$C$10:$C$161=$C23),0), _xlpm.c, MATCH(J$8,'3. Enter Indicator Scores'!$D$8:$CZ$8,0), _xlpm.v, IFERROR(INDEX('3. Enter Indicator Scores'!$D$10:$CZ$161,_xlpm.r,_xlpm.c),""), IF(OR(_xlpm.w="",_xlpm.v=""),"",_xlpm.v*_xlpm.w) )} | K23: {=_xlfn.LET( _xlpm.w, K$11, _xlpm.r, MATCH(1,('3. Enter Indicator Scores'!$B$10:$B$161=$B23)*('3. Enter Indicator Scores'!$C$10:$C$161=$C23),0), _xlpm.c, MATCH(K$8,'3. Enter Indicator Scores'!$D$8:$CZ$8,0), _xlpm.v, IFERROR(INDEX('3. Enter Indicator Scores'!$D$10:$CZ$161,_xlpm.r,_xlpm.c),""), IF(OR(_xlpm.w="",_xlpm.v=""),"",_xlpm.v*_xlpm.w) )} | ... CZ23: {=_xlfn.LET( _xlpm.w, CZ$11, _xlpm.r, MATCH(1,('3. Enter Indicator Scores'!$B$10:$B$161=$B23)*('3. Enter Indicator Scores'!$C$10:$C$161=$C23),0), _xlpm.c, MATCH(CZ$8,'3. Enter Indicator Scores'!$D$8:$CZ$8,0), _xlpm.v, IFERROR(INDEX('3. Enter Indicator Scores'!$D$10:$CZ$161,_xlpm.r,_xlpm.c),""), IF(OR(_xlpm.w="",_xlpm.v=""),"",_xlpm.v*_xlpm.w) )}
D24: {=_xlfn.LET( _xlpm.w, D$11, _xlpm.r, MATCH(1,('3. Enter Indicator Scores'!$B$10:$B$161=$B24)*('3. Enter Indicator Scores'!$C$10:$C$161=$C24),0), _xlpm.c, MATCH(D$8,'3. Enter Indicator Scores'!$D$8:$CZ$8,0), _xlpm.v, IFERROR(INDEX('3. Enter Indicator Scores'!$D$10:$CZ$161,_xlpm.r,_xlpm.c),""), IF(OR(_xlpm.w="",_xlpm.v=""),"",_xlpm.v*_xlpm.w) )} | E24: {=_xlfn.LET( _xlpm.w, E$11, _xlpm.r, MATCH(1,('3. Enter Indicator Scores'!$B$10:$B$161=$B24)*('3. Enter Indicator Scores'!$C$10:$C$161=$C24),0), _xlpm.c, MATCH(E$8,'3. Enter Indicator Scores'!$D$8:$CZ$8,0), _xlpm.v, IFERROR(INDEX('3. Enter Indicator Scores'!$D$10:$CZ$161,_xlpm.r,_xlpm.c),""), IF(OR(_xlpm.w="",_xlpm.v=""),"",_xlpm.v*_xlpm.w) )} | F24: {=_xlfn.LET( _xlpm.w, F$11, _xlpm.r, MATCH(1,('3. Enter Indicator Scores'!$B$10:$B$161=$B24)*('3. Enter Indicator Scores'!$C$10:$C$161=$C24),0), _xlpm.c, MATCH(F$8,'3. Enter Indicator Scores'!$D$8:$CZ$8,0), _xlpm.v, IFERROR(INDEX('3. Enter Indicator Scores'!$D$10:$CZ$161,_xlpm.r,_xlpm.c),""), IF(OR(_xlpm.w="",_xlpm.v=""),"",_xlpm.v*_xlpm.w) )} | G24: {=_xlfn.LET( _xlpm.w, G$11, _xlpm.r, MATCH(1,('3. Enter Indicator Scores'!$B$10:$B$161=$B24)*('3. Enter Indicator Scores'!$C$10:$C$161=$C24),0), _xlpm.c, MATCH(G$8,'3. Enter Indicator Scores'!$D$8:$CZ$8,0), _xlpm.v, IFERROR(INDEX('3. Enter Indicator Scores'!$D$10:$CZ$161,_xlpm.r,_xlpm.c),""), IF(OR(_xlpm.w="",_xlpm.v=""),"",_xlpm.v*_xlpm.w) )} | H24: {=_xlfn.LET( _xlpm.w, H$11, _xlpm.r, MATCH(1,('3. Enter Indicator Scores'!$B$10:$B$161=$B24)*('3. Enter Indicator Scores'!$C$10:$C$161=$C24),0), _xlpm.c, MATCH(H$8,'3. Enter Indicator Scores'!$D$8:$CZ$8,0), _xlpm.v, IFERROR(INDEX('3. Enter Indicator Scores'!$D$10:$CZ$161,_xlpm.r,_xlpm.c),""), IF(OR(_xlpm.w="",_xlpm.v=""),"",_xlpm.v*_xlpm.w) )} | I24: {=_xlfn.LET( _xlpm.w, I$11, _xlpm.r, MATCH(1,('3. Enter Indicator Scores'!$B$10:$B$161=$B24)*('3. Enter Indicator Scores'!$C$10:$C$161=$C24),0), _xlpm.c, MATCH(I$8,'3. Enter Indicator Scores'!$D$8:$CZ$8,0), _xlpm.v, IFERROR(INDEX('3. Enter Indicator Scores'!$D$10:$CZ$161,_xlpm.r,_xlpm.c),""), IF(OR(_xlpm.w="",_xlpm.v=""),"",_xlpm.v*_xlpm.w) )} | J24: {=_xlfn.LET( _xlpm.w, J$11, _xlpm.r, MATCH(1,('3. Enter Indicator Scores'!$B$10:$B$161=$B24)*('3. Enter Indicator Scores'!$C$10:$C$161=$C24),0), _xlpm.c, MATCH(J$8,'3. Enter Indicator Scores'!$D$8:$CZ$8,0), _xlpm.v, IFERROR(INDEX('3. Enter Indicator Scores'!$D$10:$CZ$161,_xlpm.r,_xlpm.c),""), IF(OR(_xlpm.w="",_xlpm.v=""),"",_xlpm.v*_xlpm.w) )} | K24: {=_xlfn.LET( _xlpm.w, K$11, _xlpm.r, MATCH(1,('3. Enter Indicator Scores'!$B$10:$B$161=$B24)*('3. Enter Indicator Scores'!$C$10:$C$161=$C24),0), _xlpm.c, MATCH(K$8,'3. Enter Indicator Scores'!$D$8:$CZ$8,0), _xlpm.v, IFERROR(INDEX('3. Enter Indicator Scores'!$D$10:$CZ$161,_xlpm.r,_xlpm.c),""), IF(OR(_xlpm.w="",_xlpm.v=""),"",_xlpm.v*_xlpm.w) )} | ... CZ24: {=_xlfn.LET( _xlpm.w, CZ$11, _xlpm.r, MATCH(1,('3. Enter Indicator Scores'!$B$10:$B$161=$B24)*('3. Enter Indicator Scores'!$C$10:$C$161=$C24),0), _xlpm.c, MATCH(CZ$8,'3. Enter Indicator Scores'!$D$8:$CZ$8,0), _xlpm.v, IFERROR(INDEX('3. Enter Indicator Scores'!$D$10:$CZ$161,_xlpm.r,_xlpm.c),""), IF(OR(_xlpm.w="",_xlpm.v=""),"",_xlpm.v*_xlpm.w) )}
D25: {=_xlfn.LET( _xlpm.w, D$11, _xlpm.r, MATCH(1,('3. Enter Indicator Scores'!$B$10:$B$161=$B25)*('3. Enter Indicator Scores'!$C$10:$C$161=$C25),0), _xlpm.c, MATCH(D$8,'3. Enter Indicator Scores'!$D$8:$CZ$8,0), _xlpm.v, IFERROR(INDEX('3. Enter Indicator Scores'!$D$10:$CZ$161,_xlpm.r,_xlpm.c),""), IF(OR(_xlpm.w="",_xlpm.v=""),"",_xlpm.v*_xlpm.w) )} | E25: {=_xlfn.LET( _xlpm.w, E$11, _xlpm.r, MATCH(1,('3. Enter Indicator Scores'!$B$10:$B$161=$B25)*('3. Enter Indicator Scores'!$C$10:$C$161=$C25),0), _xlpm.c, MATCH(E$8,'3. Enter Indicator Scores'!$D$8:$CZ$8,0), _xlpm.v, IFERROR(INDEX('3. Enter Indicator Scores'!$D$10:$CZ$161,_xlpm.r,_xlpm.c),""), IF(OR(_xlpm.w="",_xlpm.v=""),"",_xlpm.v*_xlpm.w) )} | F25: {=_xlfn.LET( _xlpm.w, F$11, _xlpm.r, MATCH(1,('3. Enter Indicator Scores'!$B$10:$B$161=$B25)*('3. Enter Indicator Scores'!$C$10:$C$161=$C25),0), _xlpm.c, MATCH(F$8,'3. Enter Indicator Scores'!$D$8:$CZ$8,0), _xlpm.v, IFERROR(INDEX('3. Enter Indicator Scores'!$D$10:$CZ$161,_xlpm.r,_xlpm.c),""), IF(OR(_xlpm.w="",_xlpm.v=""),"",_xlpm.v*_xlpm.w) )} | G25: {=_xlfn.LET( _xlpm.w, G$11, _xlpm.r, MATCH(1,('3. Enter Indicator Scores'!$B$10:$B$161=$B25)*('3. Enter Indicator Scores'!$C$10:$C$161=$C25),0), _xlpm.c, MATCH(G$8,'3. Enter Indicator Scores'!$D$8:$CZ$8,0), _xlpm.v, IFERROR(INDEX('3. Enter Indicator Scores'!$D$10:$CZ$161,_xlpm.r,_xlpm.c),""), IF(OR(_xlpm.w="",_xlpm.v=""),"",_xlpm.v*_xlpm.w) )} | H25: {=_xlfn.LET( _xlpm.w, H$11, _xlpm.r, MATCH(1,('3. Enter Indicator Scores'!$B$10:$B$161=$B25)*('3. Enter Indicator Scores'!$C$10:$C$161=$C25),0), _xlpm.c, MATCH(H$8,'3. Enter Indicator Scores'!$D$8:$CZ$8,0), _xlpm.v, IFERROR(INDEX('3. Enter Indicator Scores'!$D$10:$CZ$161,_xlpm.r,_xlpm.c),""), IF(OR(_xlpm.w="",_xlpm.v=""),"",_xlpm.v*_xlpm.w) )} | I25: {=_xlfn.LET( _xlpm.w, I$11, _xlpm.r, MATCH(1,('3. Enter Indicator Scores'!$B$10:$B$161=$B25)*('3. Enter Indicator Scores'!$C$10:$C$161=$C25),0), _xlpm.c, MATCH(I$8,'3. Enter Indicator Scores'!$D$8:$CZ$8,0), _xlpm.v, IFERROR(INDEX('3. Enter Indicator Scores'!$D$10:$CZ$161,_xlpm.r,_xlpm.c),""), IF(OR(_xlpm.w="",_xlpm.v=""),"",_xlpm.v*_xlpm.w) )} | J25: {=_xlfn.LET( _xlpm.w, J$11, _xlpm.r, MATCH(1,('3. Enter Indicator Scores'!$B$10:$B$161=$B25)*('3. Enter Indicator Scores'!$C$10:$C$161=$C25),0), _xlpm.c, MATCH(J$8,'3. Enter Indicator Scores'!$D$8:$CZ$8,0), _xlpm.v, IFERROR(INDEX('3. Enter Indicator Scores'!$D$10:$CZ$161,_xlpm.r,_xlpm.c),""), IF(OR(_xlpm.w="",_xlpm.v=""),"",_xlpm.v*_xlpm.w) )} | K25: {=_xlfn.LET( _xlpm.w, K$11, _xlpm.r, MATCH(1,('3. Enter Indicator Scores'!$B$10:$B$161=$B25)*('3. Enter Indicator Scores'!$C$10:$C$161=$C25),0), _xlpm.c, MATCH(K$8,'3. Enter Indicator Scores'!$D$8:$CZ$8,0), _xlpm.v, IFERROR(INDEX('3. Enter Indicator Scores'!$D$10:$CZ$161,_xlpm.r,_xlpm.c),""), IF(OR(_xlpm.w="",_xlpm.v=""),"",_xlpm.v*_xlpm.w) )} | ... CZ25: {=_xlfn.LET( _xlpm.w, CZ$11, _xlpm.r, MATCH(1,('3. Enter Indicator Scores'!$B$10:$B$161=$B25)*('3. Enter Indicator Scores'!$C$10:$C$161=$C25),0), _xlpm.c, MATCH(CZ$8,'3. Enter Indicator Scores'!$D$8:$CZ$8,0), _xlpm.v, IFERROR(INDEX('3. Enter Indicator Scores'!$D$10:$CZ$161,_xlpm.r,_xlpm.c),""), IF(OR(_xlpm.w="",_xlpm.v=""),"",_xlpm.v*_xlpm.w) )}
